## ch09 에러 처리
- 미팅을 통해 배운 내용
    - Rust에서 panic! 을 호출하는 이유는 무엇일까?
        - Rust는 복구 불가능한 에러가 발생하면 security 개념에 따라 실행중인 프로그램을 종료시켜 에러가 발생하지 않도록 막는다.
        - 소프트웨어공학의 security, reliability, safety, trustworthy 등 개념을 생각하면 좋음!   <br/><br/>


<details>
<summary> ch09 에러처리 </summary>

### 학습내용
- 복구 가능한 에러를 위한 Result\<T, E> 타입
- 복구 불가능한 에러를 위한 panic! 매크로
<br/> <br/> 

## panic! 매크로
- panic!이 발생하면 되감기(unwinding)를 시작하는데 패닉을 발생시킨 함수로부터 스택을 거꾸로 훑어가면서 데이터를 청소한다는 의미이다
- 프로그램이 데이터 정리 작업 없이 즉각 종료되는 대안인 그만두기(aborting)를 선택할 수 있다
- 프로젝트 내에서 결과 바이너리를 가능한 한 작게 만들고 싶다면 aboring 방식을 쓰면 된다
    - Cargo.toml 에 아래의 코드를 적어주면 된다
    ~~~
    [profile.release]
    panic = 'abort'
    ~~~
    - 릴리스 모드에서 패닉이 발생하면 aborting 방식으로 즉각 종료되는 것을 의미한다
<br/><br/>
- 명시적 호출
    ~~~
    fn main() {
        panic!("crash and burn");
    }
    ~~~
    - 실행 결과
    ~~~
    thread 'main' panicked at src/main.rs:2:5:
    crash and burn
    note: run with `RUST_BACKTRACE=1` environment variable to display a backtrace
    ~~~
    - 패닉이 발생한 소스 코드 지점과 메시지, 에러 메시지를 확인할 수 있다
<br/><br/>
-  유효하지 않은 인덱스 접근
    ~~~
    fn main() {
        let v = vec![1,2,3];
        v [99];
    }
    ~~~
    - 실행 결과
    ~~~
    cargo run
        Compiling panic v0.1.0 (/Users/byul/learning-rust/ch09/panic)
        Finished `dev` profile [unoptimized + debuginfo] target(s) in 0.14s
        Running `target/debug/panic`
    thread 'main' panicked at src/main.rs:7:7:
    index out of bounds: the len is 3 but the index is 99
    note: run with `RUST_BACKTRACE=1` environment variable to display a backtrace
    ~~~
    - `[]`의 사용은 어떤 요소의 반환을 가정하지만 유효하지 않은 인덱스를 넘기게 되면 러스트가 반환할 요소가 없어서 패닉을 일으킨다
    - 버퍼 오버리드 (buffer overread)
        - 데이터 구조의 끝을 넘어서 읽는 시도로 메모리가 해당 데이터 구조의 소유가 아닐지라도 데이터 구조의 해당 요소에 상응하는 메모리 위치에 있는 모든 값을 가져온다
    - 백트레이스 (backtrace)
        - 어떤 지점에 도달하기까지 호출한 모든 함수의 목록이다
        - RUST_BACKTRACE 환경 변수를 0이 아닌 값으로 설정하면 된다
        - '0'으로 입력하면 백트레이스가 비활성화된다
<br/><br/>
### Result로 복구 가능한 에러 처리하기
- match 표현식을 사용한 Result 배리언트 처리하기 (Ok, Error)
    ~~~
    let greeting_file_result = File::open("hello.txt");

    let greeting_file = match greeting_file_result {
        Ok(file) => file,
        Err(error) => panic!("Problem opening the file: {:?}", error),
    };
    ~~~
    - 결과가 Ok일 때 Ok 배리언트 내부의 file 값을 반환하고, Err일 때 panic!을 발생시킨다.
    <br/><br/>
- 다른 종류의 에러를 다른 방식으로 처리하기
    ~~~
    let greeting_file_result = File::open("hello.txt");

    let greeting_file = match greeting_file_result {
        Ok(file) => file,
        Err(error) => match error.kind() {
            ErrorKind::NotFound => match File::create("hello.txt") {
                Ok(fc) => fc,
                Err(e) => panic!("Problem creating the file: {:?}", e),
            },
            other_error => {
                panic!("Problem opening the file: {:?}", other_error);
            }
        },
    };
    ~~~
    - File::open이 반환하는 Err배리언트 값의 타입은 `io::Error`로 표준 라이브러리에서 제공하는 구조체이다
    - `kind` 메서드를 호출하여 `io::ErrorKind` 값을 얻어올 수 있다
    - ErrorKind 열거형의 `NotFound` 배리언트에 대한 매칭을 한번 더 수행한다
    - 위 코드는 중복된 match 표현식이 많다 <br/><br/>
- unwrap_or_else 메서드와 클로저
    ~~~
    let greeting_file_result = File::open("hello.txt");

    let greeting_file = File::open("Hello.txt").unwrap_or_else(|error| {
        if error.kind() == ErrorKind::NotFound {
            File::create("Hello.txt").unwrap_or_else(|error| {
                panic!("problem creating the file {:?}", error);
            })
        } else {
            panic!("problem opening the file: {:?}", error);
        }
    });
    ~~~
    - Result\<T, E>타입에는 클로저를 사용하는 여러 메서드가 있다
    - 이 메서드들로 값을 처리하면 match보다 간결하게 만들 수 있다
    - unwrap 메서드는 match 구문과 비슷한 구현을 한 숏컷 메서드로 Result 값이 Ok 배리언트라면 Ok 내의 값을 반환하고 Err 배리언트라면 panic! 메서드를 호출할 것이다
    - unwrap 메서드 사용 예시
    ~~~
    let open_file = File::open("hello.txt").unwrap();
    ~~~
    - 실행결과
    ~~~
    thread 'main' panicked at src/main.rs:39:45:
    called `Result::unwrap()` on an `Err` value: Os { code: 2, kind: NotFound, message: "No such file or directory" }
    note: run with `RUST_BACKTRACE=1` environment variable to display a backtrace
    ~~~
    - panic!의 기본 메시지만 출력된다 <br/><br/>
    - expect 메서드 사용 예시
    ~~~
    let open_file = File::open("hello.txt")
        .expect("hello.txt shoule be included in this project.");
    ~~~
    - 실행결과
    ~~~
    thread 'main' panicked at src/main.rs:40:10:
    hello.txt shoule be included in this project.: Os { code: 2, kind: NotFound, message: "No such file or directory" }
    note: run with `RUST_BACKTRACE=1` environment variable to display a backtrace
    ~~~
    - unwrap 메서드 대신 expect 메서드를 사용하면 panic! 매크로가 호출되었을 때 에러 메시지를 설정할 수 있다.<br/><br/>
- 에러 전파하기
    - 함수의 구현체에서 실패할 수도 있는 무언가를 호출할 때, 이 함수에서 에러를 처리하는 대신 호출하는 코드 쪽으로 에러를 반환하는 것을 에러 전파하기(error propagation)라고 한다
    ~~~
    use std::fs::File;
    use std::io::{self, Read};

    fn read_username_from_file() -> Result<String, io::Error> {
        let username_file_result = File::open("hello.txt");

        let mut username_file = match username_file_result {
            Ok(file) => file,
            Err(e) => return Err(e),
        };

        let mut username = String::new();

        match username_file.read_to_string(&mut username) {
            Ok(_) => Ok(username),
            Err(e) => Err(e),
        }
    }
    ~~~
    - 이 함수가 문제없이 성공하면, 함수를 호출한 코드는 String을 담은 Ok값을 받을 것이다
    - File::open이 실패하거나 성공하더라도 read_to_string이 실패할 수도 있기 때문에 2번의 match가 진행된다
    - 이 코드를 호출하는 코드는 Ok값 혹은 Err값을 처리하게 될 것이다
    - Err 값을 얻었다면 panic! 호출 혹은 기본 사용자 이름 설정 등 여러 시도를 할 수 있다
- 에러 전파를 위한 숏컷: ? 연산자
    ~~~
    use std::fs::File;
    use std::io::{self, Read};

    fn read_username_from_file() -> Result<String, io::Error> {
        let mut username_file = File::open("hello.txt")?;
        let mut username = String::new();
        username_file.read_to_string(&mut username)?;
        Ok(username)
    }
    ~~~
    - match 표현식과 거의 같은 방식으로 작동한다
    - Result의 값이 Ok라면 Ok 안의 값이 얻어지고 Err라면 return 키워드로 Err의 값이 반환될 것이다
    - match 표현식과 ? 연산자의 차이점은, `? 연산자의 에러값은 from  함수를 거친다`는 것이다
    - 모든 에러를 하나의 에러 타입으로 반환할 때 유용하다 <br/><br/>
- ? 연산자 뒤에 메서드 호출 연결하기
    ~~~
    fn read_username_from_file() -> Result<String, io::Error> {
        let mut username = String::new();
        
        File::open("hello.txt")?.read_to_string(&mut username)?;

        Ok(username)
    }
    ~~~
- fs::read_to_string 사용하기
    ~~~
    use std::fs;
    use std::io;

    fn read_username_from_file() -> Result<String, io::Error> {
        fs::read_to_string("hello.txt");
    }
    ~~~

- ? 연산자가 사용될 수 있는 곳
    - 사용된 값과 호환 가능한 반환 타입을 가진 함수에서만 사용될 수 있다
    ~~~
    use std::fs::File;

    fn main() {
        let greeting_file = File::open("hello.txt")?;
    }
    ~~~
    - 실행 결과
    ~~~
    error[E0277]: the `?` operator can only be used in a function that returns `Result` or `Option` (or another type that implements `FromResidual`)
      --> src/main.rs:4:48
      |
    3 | fn main() {
      | --------- this function should return `Result` or `Option` to accept `?`
    4 |     let greeting_file = File::open("hello.txt")?;
      |                                                ^ cannot use the `?` operator in a function that returns `()`
      |
      = help: the trait `FromResidual<Result<Infallible, std::io::Error>>` is not implemented for `()`
    ~~~
    - ? 연산자는 Result, Option 혹은 FromResidual을 구현한 타입을 반환하는 함수에서만 사용될 수 있다<br/><br/>
- Option\<T>값에 대한 ? 연산자 이용
    ~~~
    fn last_char_of_first_line(text:&str) -> Option<char> {
        text.lines().next()?.chars().last()
    }
    ~~~
- Result와 Option을 반환하는 함수에 대해 각각 ? 연산자를 쓸 수 있지만, 이를 섞어서 사용할 수는 없다
- ? 연산자는 자동으로 변환할 수 없지만, Result의 ok 메서드 혹은 Option의 ok_or 메서드 같은 것을 통해 명시적으로 변환할 수 있다

- Result 값에 대한 ? 사용 가능하게 하기
    ~~~
    use std::error::Error;
    use std::fs::File;

    fn main() -> Result<(), Box<dyn Error>> {
        let greeting_file = File::open("hello.txt")?;

        Ok(())
    }
    ~~~
    - main 함수가 Result<(), E>를 반환하게 되면 실행파일은 Ok(()) 를 반환할 경우 0 값으로 종료되고 Err 값을 반환할 경우 0이 아닌 값으로 종료된다
    - C로 작성된 실행파일은 종료될 때 정숫값을 반환한다
        - 0: 성공적으로 종료된 프로그램
        - 0 이 아닌 정수: 에러 발생
    - Rust도 C의 규칙과 호환될 목적으로 실행파일이 정숫값으로 반환한다

</details>
